Workbook

Sheet Duplicates
A1: Column1 | B1: patient_id | C1: hospital | D1: department | E1: appointment_datetime | F1: arrival_datetime | G1: discharge_datetime | H1: age | I1: gender | J1: appointment_status | K1: waiting_time_minutes | L1: consultation_duration_minutes | M1: referral_source | N1: postcode_area | O1: patient_satisfaction | P1: follow_up_required | Q1: cost_gbp | R1: data_source | S1: ID_Count
A2: A00049 | B2: P10056 | C2: Belfast City Hospital | D2: Orthopedics | E2: 45352.465 | F2: 45294.458 | G2: 45294.549 | I2: Female | J2: No-show | K2: 65 | L2: 55 | M2: Self-referral | N2: BT12 | O2: N/A | P2: N | Q2: 16.4 | R2: HIS | S2: 2
A3: A00049 | B3: P10056 | C3: Belfast City Hospital | D3: Orthopedics | E3: 45352.465 | F3: 45294.458 | G3: 45294.549 | I3: Female | J3: No-show | K3: 65 | L3: 55 | M3: Self-referral | N3: BT12 | O3: N/A | P3: N | Q3: 16.4 | R3: HIS | S3: 2
A4: A00057 | B4: P10410 | D4: Emergency | E4: 45719.462 | F4: 45719.442 | G4: 45719.552 | H4: 13 | I4: female | J4: complete | K4: 91 | L4: 39 | N4: UNKNOWN | P4: No | Q4: 210.76 | R4: LegacyDB | S4: 2
A5: A00057 | B5: P10052 | C5: Mater Hospital | D5: Cardiology | E5: 45835.635 | F5: 45835.632 | G5: 45835.74 | H5: 9 | I5: MALE | J5: Discharged | K5: 124 | L5: 27 | M5: Online | O5: N/A | P5: yes | Q5: 84.7 | R5: Legacy DB | S5: 2
A6: A00121 | B6: P10440 | C6: Mater Hosp. | D6: Emergency | E6: 06-15-2025 17:35 | F6: 45823.722 | H6: unknown | I6: Male | J6: Completed | K6: 109 | L6: 47 | M6: Emergency | N6: BT15 | O6: 3 | P6: N | Q6: 132.2 | R6: ClinicSystem | S6: 2
A7: A00121 | B7: P10440 | C7: Mater Hosp. | D7: Emergency | E7: 06-15-2025 17:35 | F7: 45823.722 | H7: unknown | I7: Male | J7: Completed | K7: 109 | L7: 47 | M7: Emergency | N7: BT15 | O7: 3 | P7: N | Q7: 132.2 | R7: ClinicSystem | S7: 2
A8: A00159 | B8: P10368 | C8: Royal Victoria Hospital | D8: CARDIOLOGY | E8: 45568.698 | F8: 45568.681 | H8: 77 | I8: Non-binary | J8: No-show | K8: 54 | L8: 28 | M8: Specialist | N8: BT15 | O8: 3 | P8: Yes | Q8: 194.13 | R8: ClinicSystem | S8: 2
A9: A00159 | B9: P10368 | C9: Royal Victoria Hospital | D9: CARDIOLOGY | E9: 45568.698 | F9: 45568.681 | H9: 77 | I9: Non-binary | J9: No-show | K9: 54 | L9: 28 | M9: Specialist | N9: BT15 | O9: 3 | P9: Yes | Q9: 194.13 | R9: ClinicSystem | S9: 2
A10: A00184 | B10: P10134 | C10: Mater Hospital | D10: Oncology | F10: 45332.717 | G10: 45332.791 | H10: 145 | I10: Non-binary | J10: Cancelled | K10: 44 | L10: 50 | N10: BT9 | Q10: 98.85 | R10: HIS | S10: 2
A11: A00184 | B11: P10076 | C11: Mater Hospital | D11: A&E | E11: 05-22-2024 14:10 | F11: 45434.577 | G11: 45434.658 | H11: 84 | I11: female | J11: DNA | K11: 87 | L11: 11 | M11: Walk-in | N11: BT2 | O11: 0 | P11: No | Q11: 187.38 | R11: HIS | S11: 2
A12: A00191 | B12: P10109 | C12: Mater Hosp. | D12: Orthopaedics | E12: 45967.372 | F12: 45967.354 | G12: 45967.428 | H12: unknown | I12: Female | J12: DNA | K12: 42 | L12: 39 | M12: Self-referral | N12: bt7 | O12: 1 | P12: N | Q12: 111.32 | R12: HIS | S12: 2
A13: A00191 | B13: P10109 | C13: Mater Hosp. | D13: Orthopaedics | E13: 45967.372 | F13: 45967.354 | G13: 45967.428 | H13: unknown | I13: Female | J13: DNA | K13: 42 | L13: 39 | M13: Self-referral | N13: bt7 | O13: 1 | P13: N | Q13: 111.32 | R13: HIS | S13: 2
A14: A00237 | B14: P10291 | C14: Belfast City Hospital | D14: Cardiology | E14: 45623.295 | F14: 45623.291 | G14: 45623.379 | H14: -4 | I14: MALE | J14: Discharged | K14: 79 | L14: 42 | M14: GP | N14: BT7 | O14: N/A | P14: N | Q14: 120.24 | R14: Legacy DB | S14: 2
A15: A00237 | B15: P10295 | C15: RVH | D15: Orthopedics | E15: 45349.639 | F15: 45349.619 | G15: 45349.693 | I15: Female | J15: Discharged | K15: 69 | L15: 9 | M15: Walk-in | N15: bt7 | O15: 6 | P15: yes | Q15: 218.92 | R15: Legacy DB | S15: 2
A16: A00276 | B16: P10089 | C16: Mater Hospital | D16: Oncology | E16: 45965.406 | F16: 45758.404 | H16: 73 | I16: MALE | J16: No-show | K16: 101 | L16: 15 | M16: GP | N16: BT15 | O16: 6 | P16: No | R16: LegacyDB | S16: 2
A17: A00276 | B17: P10089 | C17: Mater Hospital | D17: Oncology | E17: 45965.406 | F17: 45758.404 | H17: 73 | I17: MALE | J17: No-show | K17: 101 | L17: 15 | M17: GP | N17: BT15 | O17: 6 | P17: No | R17: LegacyDB | S17: 2
A18: A00289 | B18: P10437 | C18: Mater Hosp. | D18: Orthopedics | E18: 45611.733 | F18: 45611.731 | G18: 45611.806 | I18: F | J18: DNA | K18: 71 | L18: 34 | M18: GP | N18: BT99 | O18: 0 | P18: yes | Q18: 184.4 | R18: HIS | S18: 2
A19: A00289 | B19: P10102 | C19: Mater Hosp. | D19: Cardiology | E19: 45396.757 | F19: 45396.739 | G19: 45396.857 | H19: unknown | J19: Cancelled | K19: 68 | L19: 76 | M19: GP | N19: bt7 | O19: N/A | P19: yes | Q19: 93.98 | R19: HIS | S19: 2
A20: A00347 | B20: P10246 | D20: Out Patient | E20: 45908.41 | F20: 45878.407 | G20: 45878.476 | K20: 33 | L20: 63 | N20: UNKNOWN | O20: 6 | P20: yes | Q20: 160.83 | R20: ClinicSystem | S20: 2
A21: A00347 | B21: P10419 | C21: Belfast City Hospital | D21: Emergency | E21: 45300.656 | F21: 45300.652 | G21: 45300.697 | H21: 81 | I21: Prefer not to say | J21: No-show | K21: 35 | L21: 23 | M21: Specialist | N21: BT99 | O21: N/A | P21: Y | Q21: 119.37 | R21: Legacy DB | S21: 2
A22: A00368 | B22: P10219 | C22: Ulster Hospital | D22: Out Patient | E22: 45305.417 | F22: 45305.416 | G22: 45305.464 | H22: 37 | I22: F | J22: Cancelled | K22: 60 | L22: 8 | N22: BT9 | O22: N/A | P22: yes | Q22: 224.7 | R22: HIS | S22: 2
A23: A00368 | B23: P10117 | C23: RVH | D23: Pediatrics | E23: 10-21-2025 07:40 | F23: 45951.315 | G23: 45951.351 | H23: unknown | I23: M | J23: complete | K23: 40 | L23: 5 | N23: UNKNOWN | O23: 0 | P23: No | R23: HIS | S23: 2
A24: A00383 | B24: P10382 | C24: Belfast City Hospital | D24: Accident & Emergency | E24: 10-30-2024 10:35 | F24: 45595.435 | G24: 45595.56 | J24: CANCELLED | K24: 142 | L24: 30 | M24: Online | N24: BT9 | O24: N/A | P24: N | R24: LegacyDB | S24: 2
A25: A00383 | B25: P10382 | C25: Belfast City Hospital | D25: Accident & Emergency | E25: 10-30-2024 10:35 | F25: 45595.435 | G25: 45595.56 | J25: CANCELLED | K25: 142 | L25: 30 | M25: Online | N25: BT9 | O25: N/A | P25: N | R25: LegacyDB | S25: 2
A26: A00385 | B26: P10155 | D26: Cardiology | E26: 45853.545 | F26: 45853.533 | G26: 45853.644 | I26: F | J26: No-show | K26: 99 | L26: 43 | M26: Specialist | N26: BT9 | P26: No | Q26: 53.56 | R26: HIS | S26: 2
A27: A00385 | B27: P10091 | C27: Belfast City Hospital | D27: A&E | E27: 03-13-2025 17:10 | F27: 45729.704 | G27: 45729.803 | H27: 55 | I27: female | J27: Completed | K27: 115 | L27: 11 | M27: Specialist | N27: BT1 | O27: 0 | P27: N | Q27: 169.21 | R27: Legacy DB | S27: 2
A28: A00511 | B28: P10262 | C28: Ulster Hospital | D28: Oncology | E28: 11-29-2025 11:15 | F28: 45990.459 | G28: 45990.554 | H28: unknown | I28: F | J28: Discharged | K28: 64 | L28: 59 | M28: Online | N28: BT7 | P28: Y | Q28: 305.49 | R28: Legacy DB | S28: 2
A29: A00511 | B29: P10262 | C29: Ulster Hospital | D29: Oncology | E29: 11-29-2025 11:15 | F29: 45990.459 | G29: 45990.554 | H29: unknown | I29: F | J29: Discharged | K29: 64 | L29: 59 | M29: Online | N29: BT7 | P29: Y | Q29: 305.49 | R29: Legacy DB | S29: 2
A30: A00612 | B30: P10105 | D30: Outpatient | F30: 45815.297 | G30: 45815.369 | H30: 145 | I30: F | J30: Completed | K30: 62 | L30: 29 | M30: Online | N30: BT99 | Q30: 198.71 | R30: ClinicSystem | S30: 2
A31: A00612 | B31: P10227 | C31: Mater Hosp. | D31: Out Patient | E31: 45323.667 | F31: 45323.646 | G31: 45323.724 | H31: 47 | I31: M | J31: Completed | K31: 65 | L31: 18 | N31: BT15 | O31: 0 | P31: No | R31: HIS | S31: 2
A32: A00680 | B32: P10230 | C32: Ulster Hospital | D32: Orthopaedics | E32: 45506.424 | F32: 45506.423 | I32: Non-binary | J32: Pending | K32: 84 | L32: 53 | N32: BT7 | O32: 0 | P32: N | R32: LegacyDB | S32: 2
A33: A00680 | B33: P10230 | C33: Ulster Hospital | D33: Orthopaedics | E33: 45506.424 | F33: 45506.423 | I33: Non-binary | J33: Pending | K33: 84 | L33: 53 | N33: BT7 | O33: 0 | P33: N | R33: LegacyDB | S33: 2
A34: A00689 | B34: P10320 | C34: Belfast city hospital | D34: Oncology | E34: 45833.361 | F34: 45833.347 | G34: 45833.441 | H34: 63 | I34: Unknown | K34: 87 | L34: 28 | M34: Specialist | N34: bt7 | O34: N/A | P34: Yes | Q34: 123.84 | R34: ClinicSystem | S34: 2
A35: A00689 | B35: P10152 | C35: Mater Hospital | D35: Orthopedics | E35: 09-25-2025 17:20 | G35: 45925.752 | I35: Unknown | J35: No-show | K35: 0 | L35: 43 | N35: BT9 | P35: Yes | Q35: 45.86 | R35: HIS | S35: 2
A36: A00700 | B36: P10152 | C36: Ulster Hospital | D36: Neurology | E36: 45859.319 | F36: 45859.305 | G36: 45859.377 | H36: 67 | I36: female | J36: CANCELLED | K36: 57 | L36: 26 | M36: GP | N36: BT9 | O36: 6 | P36: No | Q36: 157.42 | R36: HIS | S36: 2
A37: A00700 | B37: P10146 | C37: Mater Hospital | D37: Paediatrics | E37: 45912.319 | F37: 45912.304 | G37: 45912.39 | H37: 74 | I37: female | J37: Discharged | K37: 86 | L37: 16 | O37: N/A | P37: Y | Q37: 92.35 | R37: Legacy DB | S37: 2
A38: A00740 | B38: P10295 | C38: RVH | D38: Accident & Emergency | E38: 07-25-2025 17:30 | F38: 45863.726 | G38: 45863.756 | H38: 48 | K38: 29 | L38: 9 | M38: Specialist | N38: BT15 | O38: 3 | Q38: 126.28 | R38: HIS | S38: 2
A39: A00740 | B39: P10117 | D39: GP Referral | E39: 45902.507 | F39: 45902.501 | G39: 45902.592 | I39: Unknown | J39: CANCELLED | K39: 74 | L39: 49 | M39: Walk-in | N39: bt7 | O39: 2 | R39: HIS | S39: 2
A40: A00844 | B40: P10127 | C40: Belfast City Hospital | D40: Paediatrics | E40: 03-24-2025 13:10 | F40: 45740.535 | G40: 45740.574 | H40: 10 | I40: M | J40: CANCELLED | K40: 30 | L40: 7 | M40: GP | N40: BT99 | O40: 2 | P40: No | Q40: 169.31 | R40: ClinicSystem | S40: 2
...

Sheet Raw Data
A1: Appoinment_id | B1: patient_id | C1: Hospital | D1: department | E1: appointment_datetime | F1: arrival_datetime | G1: discharge_datetime | H1: Age | I1: gender | J1: appointment_status | K1: waiting_time_minutes | L1: consultation_duration_minutes | M1: referral_source | N1: postcode_area | O1: patient_satisfaction | P1: follow_up_required | Q1: cost_gbp | R1: data_source | S1: ID_Count | T1: Age_Check | U1: Age_cleaned | V1: Wait_time_check | W1: Comparison | X1: D_Compare
A2: A00001 | B2: P10377 | C2: Royal Victoria Hospital | D2: Outpatient | E2: 45946.333 | F2: 45946.314 | G2: 45946.406 | H2: 75 | I2: F | J2: Pending | K2: 75 | L2: 29 | M2: Emergency | N2: BT9 | O2: 6 | P2: Yes | Q2: 196.82 | R2: Legacy DB | S2: =COUNTIF(A:A,A2) -> 1 | T2: =IF(OR(H2="",LOWER(TRIM(H2&""))="missing",LOWER(TRIM(H2&""))=""),"Missing/",IFERROR(IF(OR(VALUE(H2)<0,VALUE(H2)>110),"Invalid","Valid"),"Check Format")) -> Valid | U2: =IF(Raw_Data[[#This Row],[Age_Check]]="Valid",H2,"") -> 75 | V2: =IF(OR(K2="",UPPER(TRIM(K2&""))="",LOWER(TRIM(K2&""))="",LOWER(TRIM(K2&""))="",LOWER(TRIM(K2&""))="missing"),"Missing/",IFERROR(IF(VALUE(K2)<0,"Invalid","Valid"),"Check Format")) -> Valid | W2: =IF(OR(E2="",F2=""),"Missing Date/Time",IFERROR(IF(F2>E2,"Arrival After Appointment","OK"),"Check Format")) -> OK | X2: =IF(OR(F2="",G2=""),"Missing Date/Time",IFERROR(IF(G2<F2,"Discharge Before Arrival","OK"),"Check Format")) -> OK
A3: A00002 | B3: P10110 | C3: RVH | D3: Cardiology | E3: 45474.413 | F3: 45298.405 | I3: F | J3: Completed | K3: 111 | L3: 27 | M3: Online | O3: 1 | P3: Yes | Q3: 126.27 | R3: Legacy DB | S3: =COUNTIF(A:A,A3) -> 1 | T3: =IF(OR(H3="",LOWER(TRIM(H3&""))="missing",LOWER(TRIM(H3&""))=""),"Missing/",IFERROR(IF(OR(VALUE(H3)<0,VALUE(H3)>110),"Invalid","Valid"),"Check Format")) -> Missing/ | U3: =IF(Raw_Data[[#This Row],[Age_Check]]="Valid",H3,"") | V3: =IF(OR(K3="",UPPER(TRIM(K3&""))="",LOWER(TRIM(K3&""))="",LOWER(TRIM(K3&""))="",LOWER(TRIM(K3&""))="missing"),"Missing/",IFERROR(IF(VALUE(K3)<0,"Invalid","Valid"),"Check Format")) -> Valid | W3: =IF(OR(E3="",F3=""),"Missing Date/Time",IFERROR(IF(F3>E3,"Arrival After Appointment","OK"),"Check Format")) -> OK | X3: =IF(OR(F3="",G3=""),"Missing Date/Time",IFERROR(IF(G3<F3,"Discharge Before Arrival","OK"),"Check Format")) -> Missing Date/Time
A4: A00003 | B4: P10437 | C4: Ulster Hospital | D4: Neurology | E4: 45629.326 | F4: 45363.318 | G4: 45363.436 | H4: 46 | I4: Prefer not to say | J4: D | K4: 113 | L4: 45 | M4: Walk-in | N4: BT9 | O4: 6 | P4: No | Q4: 107.44 | R4: ClinicSystem | S4: =COUNTIF(A:A,A4) -> 1 | T4: =IF(OR(H4="",LOWER(TRIM(H4&""))="missing",LOWER(TRIM(H4&""))=""),"Missing/",IFERROR(IF(OR(VALUE(H4)<0,VALUE(H4)>110),"Invalid","Valid"),"Check Format")) -> Valid | U4: =IF(Raw_Data[[#This Row],[Age_Check]]="Valid",H4,"") -> 46 | V4: =IF(OR(K4="",UPPER(TRIM(K4&""))="",LOWER(TRIM(K4&""))="",LOWER(TRIM(K4&""))="",LOWER(TRIM(K4&""))="missing"),"Missing/",IFERROR(IF(VALUE(K4)<0,"Invalid","Valid"),"Check Format")) -> Valid | W4: =IF(OR(E4="",F4=""),"Missing Date/Time",IFERROR(IF(F4>E4,"Arrival After Appointment","OK"),"Check Format")) -> OK | X4: =IF(OR(F4="",G4=""),"Missing Date/Time",IFERROR(IF(G4<F4,"Discharge Before Arrival","OK"),"Check Format")) -> OK
A5: A00004 | B5: P10117 | C5: Belfast City Hospital | D5: Pediatrics | E5: 10-17-2025 18:40 | F5: 45947.769 | G5: 45947.847 | I5: Prefer not to say | J5: D | K5: 76 | L5: 23 | M5: Specialist | N5: BT9 | O5: 4 | P5: Yes | Q5: 107.74 | R5: Legacy DB | S5: =COUNTIF(A:A,A5) -> 1 | T5: =IF(OR(H5="",LOWER(TRIM(H5&""))="missing",LOWER(TRIM(H5&""))=""),"Missing/",IFERROR(IF(OR(VALUE(H5)<0,VALUE(H5)>110),"Invalid","Valid"),"Check Format")) -> Missing/ | U5: =IF(Raw_Data[[#This Row],[Age_Check]]="Valid",H5,"") | V5: =IF(OR(K5="",UPPER(TRIM(K5&""))="",LOWER(TRIM(K5&""))="",LOWER(TRIM(K5&""))="",LOWER(TRIM(K5&""))="missing"),"Missing/",IFERROR(IF(VALUE(K5)<0,"Invalid","Valid"),"Check Format")) -> Valid | W5: =IF(OR(E5="",F5=""),"Missing Date/Time",IFERROR(IF(F5>E5,"Arrival After Appointment","OK"),"Check Format")) -> OK | X5: =IF(OR(F5="",G5=""),"Missing Date/Time",IFERROR(IF(G5<F5,"Discharge Before Arrival","OK"),"Check Format")) -> OK
A6: A00005 | B6: P10386 | C6: Belfast City Hospital | D6: Accident & Emergency | E6: 45889.559 | F6: 45889.556 | G6: 45889.608 | H6: 145 | I6: M | J6: D | K6: 66 | L6: 5 | N6: BT7 | O6: 6 | P6: Yes | Q6: 7.01 | R6: HIS | S6: =COUNTIF(A:A,A6) -> 1 | T6: =IF(OR(H6="",LOWER(TRIM(H6&""))="missing",LOWER(TRIM(H6&""))=""),"Missing/",IFERROR(IF(OR(VALUE(H6)<0,VALUE(H6)>110),"Invalid","Valid"),"Check Format")) -> Invalid | U6: =IF(Raw_Data[[#This Row],[Age_Check]]="Valid",H6,"") | V6: =IF(OR(K6="",UPPER(TRIM(K6&""))="",LOWER(TRIM(K6&""))="",LOWER(TRIM(K6&""))="",LOWER(TRIM(K6&""))="missing"),"Missing/",IFERROR(IF(VALUE(K6)<0,"Invalid","Valid"),"Check Format")) -> Valid | W6: =IF(OR(E6="",F6=""),"Missing Date/Time",IFERROR(IF(F6>E6,"Arrival After Appointment","OK"),"Check Format")) -> OK | X6: =IF(OR(F6="",G6=""),"Missing Date/Time",IFERROR(IF(G6<F6,"Discharge Before Arrival","OK"),"Check Format")) -> OK
A7: A00006 | B7: P10232 | C7: Belfast City Hospital | D7: Out Patient | E7: 45565.726 | F7: 45565.706 | G7: 45565.761 | H7: 145 | I7: M | J7: Cancelled | K7: 38 | L7: 13 | M7: GP | O7: 2 | P7: Yes | Q7: 170.14 | R7: Legacy DB | S7: =COUNTIF(A:A,A7) -> 1 | T7: =IF(OR(H7="",LOWER(TRIM(H7&""))="missing",LOWER(TRIM(H7&""))=""),"Missing/",IFERROR(IF(OR(VALUE(H7)<0,VALUE(H7)>110),"Invalid","Valid"),"Check Format")) -> Invalid | U7: =IF(Raw_Data[[#This Row],[Age_Check]]="Valid",H7,"") | V7: =IF(OR(K7="",UPPER(TRIM(K7&""))="",LOWER(TRIM(K7&""))="",LOWER(TRIM(K7&""))="",LOWER(TRIM(K7&""))="missing"),"Missing/",IFERROR(IF(VALUE(K7)<0,"Invalid","Valid"),"Check Format")) -> Valid | W7: =IF(OR(E7="",F7=""),"Missing Date/Time",IFERROR(IF(F7>E7,"Arrival After Appointment","OK"),"Check Format")) -> OK | X7: =IF(OR(F7="",G7=""),"Missing Date/Time",IFERROR(IF(G7<F7,"Discharge Before Arrival","OK"),"Check Format")) -> OK
A8: A00007 | B8: P10122 | C8: Belfast City Hospital | D8: A&E | E8: 45786.524 | F8: 45905.512 | G8: 45905.547 | I8: M | J8: Completed | K8: 26 | L8: 6 | M8: Self-referral | N8: BT7 | O8: 5 | P8: Yes | Q8: 262.25 | R8: Legacy DB | S8: =COUNTIF(A:A,A8) -> 1 | T8: =IF(OR(H8="",LOWER(TRIM(H8&""))="missing",LOWER(TRIM(H8&""))=""),"Missing/",IFERROR(IF(OR(VALUE(H8)<0,VALUE(H8)>110),"Invalid","Valid"),"Check Format")) -> Missing/ | U8: =IF(Raw_Data[[#This Row],[Age_Check]]="Valid",H8,"") | V8: =IF(OR(K8="",UPPER(TRIM(K8&""))="",LOWER(TRIM(K8&""))="",LOWER(TRIM(K8&""))="",LOWER(TRIM(K8&""))="missing"),"Missing/",IFERROR(IF(VALUE(K8)<0,"Invalid","Valid"),"Check Format")) -> Valid | W8: =IF(OR(E8="",F8=""),"Missing Date/Time",IFERROR(IF(F8>E8,"Arrival After Appointment","OK"),"Check Format")) -> Arrival After Appointment | X8: =IF(OR(F8="",G8=""),"Missing Date/Time",IFERROR(IF(G8<F8,"Discharge Before Arrival","OK"),"Check Format")) -> OK
A9: A00008 | B9: P10264 | D9: CARDIOLOGY | E9: 45850.455 | F9: 45998.45 | H9: 145 | I9: M | J9: Pending | K9: 50 | L9: 33 | M9: Specialist | N9: BT1 | O9: 1 | P9: Yes | Q9: 31.02 | R9: LegacyDB | S9: =COUNTIF(A:A,A9) -> 1 | T9: =IF(OR(H9="",LOWER(TRIM(H9&""))="missing",LOWER(TRIM(H9&""))=""),"Missing/",IFERROR(IF(OR(VALUE(H9)<0,VALUE(H9)>110),"Invalid","Valid"),"Check Format")) -> Invalid | U9: =IF(Raw_Data[[#This Row],[Age_Check]]="Valid",H9,"") | V9: =IF(OR(K9="",UPPER(TRIM(K9&""))="",LOWER(TRIM(K9&""))="",LOWER(TRIM(K9&""))="",LOWER(TRIM(K9&""))="missing"),"Missing/",IFERROR(IF(VALUE(K9)<0,"Invalid","Valid"),"Check Format")) -> Valid | W9: =IF(OR(E9="",F9=""),"Missing Date/Time",IFERROR(IF(F9>E9,"Arrival After Appointment","OK"),"Check Format")) -> Arrival After Appointment | X9: =IF(OR(F9="",G9=""),"Missing Date/Time",IFERROR(IF(G9<F9,"Discharge Before Arrival","OK"),"Check Format")) -> Missing Date/Time
A10: A00009 | B10: P10097 | C10: Royal Victoria Hospital | D10: Outpatient | E10: 31/02/2025 10:00 | F10: 45511.623 | G10: 45511.681 | I10: F | J10: Cancelled | K10: 38 | L10: 33 | M10: Emergency | N10: BT1 | O10: 4 | P10: No | Q10: 52.92 | R10: Legacy DB | S10: =COUNTIF(A:A,A10) -> 1 | T10: =IF(OR(H10="",LOWER(TRIM(H10&""))="missing",LOWER(TRIM(H10&""))=""),"Missing/",IFERROR(IF(OR(VALUE(H10)<0,VALUE(H10)>110),"Invalid","Valid"),"Check Format")) -> Missing/ | U10: =IF(Raw_Data[[#This Row],[Age_Check]]="Valid",H10,"") | V10: =IF(OR(K10="",UPPER(TRIM(K10&""))="",LOWER(TRIM(K10&""))="",LOWER(TRIM(K10&""))="",LOWER(TRIM(K10&""))="missing"),"Missing/",IFERROR(IF(VALUE(K10)<0,"Invalid","Valid"),"Check Format")) -> Valid | W10: =IF(OR(E10="",F10=""),"Missing Date/Time",IFERROR(IF(F10>E10,"Arrival After Appointment","OK"),"Check Format")) -> OK | X10: =IF(OR(F10="",G10=""),"Missing Date/Time",IFERROR(IF(G10<F10,"Discharge Before Arrival","OK"),"Check Format")) -> OK
A11: A00010 | B11: P10276 | C11: Belfast City Hospital | D11: A&E | E11: 45547.358 | F11: 45547.338 | G11: 45547.422 | I11: M | K11: 71 | L11: 21 | M11: Online | N11: BT9 | O11: 1 | P11: No | R11: HIS | S11: =COUNTIF(A:A,A11) -> 1 | T11: =IF(OR(H11="",LOWER(TRIM(H11&""))="missing",LOWER(TRIM(H11&""))=""),"Missing/",IFERROR(IF(OR(VALUE(H11)<0,VALUE(H11)>110),"Invalid","Valid"),"Check Format")) -> Missing/ | U11: =IF(Raw_Data[[#This Row],[Age_Check]]="Valid",H11,"") | V11: =IF(OR(K11="",UPPER(TRIM(K11&""))="",LOWER(TRIM(K11&""))="",LOWER(TRIM(K11&""))="",LOWER(TRIM(K11&""))="missing"),"Missing/",IFERROR(IF(VALUE(K11)<0,"Invalid","Valid"),"Check Format")) -> Valid | W11: =IF(OR(E11="",F11=""),"Missing Date/Time",IFERROR(IF(F11>E11,"Arrival After Appointment","OK"),"Check Format")) -> OK | X11: =IF(OR(F11="",G11=""),"Missing Date/Time",IFERROR(IF(G11<F11,"Discharge Before Arrival","OK"),"Check Format")) -> OK
A12: A00011 | B12: P10097 | C12: Belfast City Hospital | D12: Pediatrics | E12: 45725.788 | F12: 45725.787 | G12: 45725.835 | I12: Prefer not to say | K12: 47 | L12: 21 | M12: GP | N12: BT1 | O12: 6 | Q12: 293.18 | R12: HIS | S12: =COUNTIF(A:A,A12) -> 1 | T12: =IF(OR(H12="",LOWER(TRIM(H12&""))="missing",LOWER(TRIM(H12&""))=""),"Missing/",IFERROR(IF(OR(VALUE(H12)<0,VALUE(H12)>110),"Invalid","Valid"),"Check Format")) -> Missing/ | U12: =IF(Raw_Data[[#This Row],[Age_Check]]="Valid",H12,"") | V12: =IF(OR(K12="",UPPER(TRIM(K12&""))="",LOWER(TRIM(K12&""))="",LOWER(TRIM(K12&""))="",LOWER(TRIM(K12&""))="missing"),"Missing/",IFERROR(IF(VALUE(K12)<0,"Invalid","Valid"),"Check Format")) -> Valid | W12: =IF(OR(E12="",F12=""),"Missing Date/Time",IFERROR(IF(F12>E12,"Arrival After Appointment","OK"),"Check Format")) -> OK | X12: =IF(OR(F12="",G12=""),"Missing Date/Time",IFERROR(IF(G12<F12,"Discharge Before Arrival","OK"),"Check Format")) -> OK
A13: A00012 | B13: P10126 | C13: Belfast City Hospital | D13: CARDIOLOGY | E13: 45901.368 | F13: 45901.359 | G13: 45901.416 | I13: Non-binary | J13: D | K13: 57 | L13: 12 | M13: Specialist | N13: BT15 | O13: 0 | P13: No | Q13: 210.8 | R13: LegacyDB | S13: =COUNTIF(A:A,A13) -> 1 | T13: =IF(OR(H13="",LOWER(TRIM(H13&""))="missing",LOWER(TRIM(H13&""))=""),"Missing/",IFERROR(IF(OR(VALUE(H13)<0,VALUE(H13)>110),"Invalid","Valid"),"Check Format")) -> Missing/ | U13: =IF(Raw_Data[[#This Row],[Age_Check]]="Valid",H13,"") | V13: =IF(OR(K13="",UPPER(TRIM(K13&""))="",LOWER(TRIM(K13&""))="",LOWER(TRIM(K13&""))="",LOWER(TRIM(K13&""))="missing"),"Missing/",IFERROR(IF(VALUE(K13)<0,"Invalid","Valid"),"Check Format")) -> Valid | W13: =IF(OR(E13="",F13=""),"Missing Date/Time",IFERROR(IF(F13>E13,"Arrival After Appointment","OK"),"Check Format")) -> OK | X13: =IF(OR(F13="",G13=""),"Missing Date/Time",IFERROR(IF(G13<F13,"Discharge Before Arrival","OK"),"Check Format")) -> OK
A14: A00013 | B14: P10135 | C14: Mater Hospital | D14: A&E | E14: 45301.615 | F14: 45301.595 | I14: F | J14: Cancelled | K14: 15 | L14: 35 | M14: Online | P14: Yes | R14: Legacy DB | S14: =COUNTIF(A:A,A14) -> 1 | T14: =IF(OR(H14="",LOWER(TRIM(H14&""))="missing",LOWER(TRIM(H14&""))=""),"Missing/",IFERROR(IF(OR(VALUE(H14)<0,VALUE(H14)>110),"Invalid","Valid"),"Check Format")) -> Missing/ | U14: =IF(Raw_Data[[#This Row],[Age_Check]]="Valid",H14,"") | V14: =IF(OR(K14="",UPPER(TRIM(K14&""))="",LOWER(TRIM(K14&""))="",LOWER(TRIM(K14&""))="",LOWER(TRIM(K14&""))="missing"),"Missing/",IFERROR(IF(VALUE(K14)<0,"Invalid","Valid"),"Check Format")) -> Valid | W14: =IF(OR(E14="",F14=""),"Missing Date/Time",IFERROR(IF(F14>E14,"Arrival After Appointment","OK"),"Check Format")) -> OK | X14: =IF(OR(F14="",G14=""),"Missing Date/Time",IFERROR(IF(G14<F14,"Discharge Before Arrival","OK"),"Check Format")) -> Missing Date/Time
A15: A00014 | B15: P10144 | C15: Ulster Hospital | D15: Oncology | E15: 45429.462 | F15: 45429.458 | G15: 45429.467 | I15: Non-binary | J15: Cancelled | K15: 0 | L15: 8 | M15: GP | N15: BT2 | O15: 4 | P15: Yes | Q15: 160.75 | R15: ClinicSystem | S15: =COUNTIF(A:A,A15) -> 1 | T15: =IF(OR(H15="",LOWER(TRIM(H15&""))="missing",LOWER(TRIM(H15&""))=""),"Missing/",IFERROR(IF(OR(VALUE(H15)<0,VALUE(H15)>110),"Invalid","Valid"),"Check Format")) -> Missing/ | U15: =IF(Raw_Data[[#This Row],[Age_Check]]="Valid",H15,"") | V15: =IF(OR(K15="",UPPER(TRIM(K15&""))="",LOWER(TRIM(K15&""))="",LOWER(TRIM(K15&""))="",LOWER(TRIM(K15&""))="missing"),"Missing/",IFERROR(IF(VALUE(K15)<0,"Invalid","Valid"),"Check Format")) -> Valid | W15: =IF(OR(E15="",F15=""),"Missing Date/Time",IFERROR(IF(F15>E15,"Arrival After Appointment","OK"),"Check Format")) -> OK | X15: =IF(OR(F15="",G15=""),"Missing Date/Time",IFERROR(IF(G15<F15,"Discharge Before Arrival","OK"),"Check Format")) -> OK
A16: A00015 | B16: P10353 | C16: Mater Hospital | D16: Emergency | E16: 45856.771 | F16: 45856.753 | G16: 45856.853 | I16: F | K16: 83 | L16: 35 | M16: GP | N16: BT12 | P16: No | Q16: 135.75 | R16: HIS | S16: =COUNTIF(A:A,A16) -> 1 | T16: =IF(OR(H16="",LOWER(TRIM(H16&""))="missing",LOWER(TRIM(H16&""))=""),"Missing/",IFERROR(IF(OR(VALUE(H16)<0,VALUE(H16)>110),"Invalid","Valid"),"Check Format")) -> Missing/ | U16: =IF(Raw_Data[[#This Row],[Age_Check]]="Valid",H16,"") | V16: =IF(OR(K16="",UPPER(TRIM(K16&""))="",LOWER(TRIM(K16&""))="",LOWER(TRIM(K16&""))="",LOWER(TRIM(K16&""))="missing"),"Missing/",IFERROR(IF(VALUE(K16)<0,"Invalid","Valid"),"Check Format")) -> Valid | W16: =IF(OR(E16="",F16=""),"Missing Date/Time",IFERROR(IF(F16>E16,"Arrival After Appointment","OK"),"Check Format")) -> OK | X16: =IF(OR(F16="",G16=""),"Missing Date/Time",IFERROR(IF(G16<F16,"Discharge Before Arrival","OK"),"Check Format")) -> OK
A17: A00016 | B17: P10211 | C17: Belfast City Hospital | D17: GP Referral | E17: 45927.757 | F17: 45927.737 | G17: 45927.793 | I17: M | J17: D | K17: 47 | L17: 5 | M17: GP | N17: BT7 | O17: 1 | Q17: 87.41 | R17: ClinicSystem | S17: =COUNTIF(A:A,A17) -> 1 | T17: =IF(OR(H17="",LOWER(TRIM(H17&""))="missing",LOWER(TRIM(H17&""))=""),"Missing/",IFERROR(IF(OR(VALUE(H17)<0,VALUE(H17)>110),"Invalid","Valid"),"Check Format")) -> Missing/ | U17: =IF(Raw_Data[[#This Row],[Age_Check]]="Valid",H17,"") | V17: =IF(OR(K17="",UPPER(TRIM(K17&""))="",LOWER(TRIM(K17&""))="",LOWER(TRIM(K17&""))="",LOWER(TRIM(K17&""))="missing"),"Missing/",IFERROR(IF(VALUE(K17)<0,"Invalid","Valid"),"Check Format")) -> Valid | W17: =IF(OR(E17="",F17=""),"Missing Date/Time",IFERROR(IF(F17>E17,"Arrival After Appointment","OK"),"Check Format")) -> OK | X17: =IF(OR(F17="",G17=""),"Missing Date/Time",IFERROR(IF(G17<F17,"Discharge Before Arrival","OK"),"Check Format")) -> OK
A18: A00017 | B18: P10442 | C18: Royal Victoria Hospital | D18: CARDIOLOGY | E18: 08-21-2024 10:00 | F18: 45525.411 | G18: 45525.481 | J18: D | K18: 41 | L18: 51 | M18: Walk-in | N18: BT1 | O18: 3 | P18: Yes | Q18: 172.49 | R18: LegacyDB | S18: =COUNTIF(A:A,A18) -> 1 | T18: =IF(OR(H18="",LOWER(TRIM(H18&""))="missing",LOWER(TRIM(H18&""))=""),"Missing/",IFERROR(IF(OR(VALUE(H18)<0,VALUE(H18)>110),"Invalid","Valid"),"Check Format")) -> Missing/ | U18: =IF(Raw_Data[[#This Row],[Age_Check]]="Valid",H18,"") | V18: =IF(OR(K18="",UPPER(TRIM(K18&""))="",LOWER(TRIM(K18&""))="",LOWER(TRIM(K18&""))="",LOWER(TRIM(K18&""))="missing"),"Missing/",IFERROR(IF(VALUE(K18)<0,"Invalid","Valid"),"Check Format")) -> Valid | W18: =IF(OR(E18="",F18=""),"Missing Date/Time",IFERROR(IF(F18>E18,"Arrival After Appointment","OK"),"Check Format")) -> OK | X18: =IF(OR(F18="",G18=""),"Missing Date/Time",IFERROR(IF(G18<F18,"Discharge Before Arrival","OK"),"Check Format")) -> OK
A19: A00018 | B19: P10097 | C19: Belfast City Hospital | D19: A&E | E19: 45613.573 | G19: 45613.599 | I19: M | K19: 0 | L19: 37 | M19: Walk-in | N19: BT7 | O19: 6 | P19: Yes | Q19: 114.19 | R19: HIS | S19: =COUNTIF(A:A,A19) -> 1 | T19: =IF(OR(H19="",LOWER(TRIM(H19&""))="missing",LOWER(TRIM(H19&""))=""),"Missing/",IFERROR(IF(OR(VALUE(H19)<0,VALUE(H19)>110),"Invalid","Valid"),"Check Format")) -> Missing/ | U19: =IF(Raw_Data[[#This Row],[Age_Check]]="Valid",H19,"") | V19: =IF(OR(K19="",UPPER(TRIM(K19&""))="",LOWER(TRIM(K19&""))="",LOWER(TRIM(K19&""))="",LOWER(TRIM(K19&""))="missing"),"Missing/",IFERROR(IF(VALUE(K19)<0,"Invalid","Valid"),"Check Format")) -> Valid | W19: =IF(OR(E19="",F19=""),"Missing Date/Time",IFERROR(IF(F19>E19,"Arrival After Appointment","OK"),"Check Format")) -> Missing Date/Time | X19: =IF(OR(F19="",G19=""),"Missing Date/Time",IFERROR(IF(G19<F19,"Discharge Before Arrival","OK"),"Check Format")) -> Missing Date/Time
A20: A00019 | B20: P10215 | C20: Mater Hospital | D20: Orthopedics | E20: 45710.521 | F20: 45710.501 | G20: 45710.574 | J20: Pending | K20: 34 | L20: 43 | M20: GP | N20: BT12 | O20: 0 | Q20: 227.48 | R20: LegacyDB | S20: =COUNTIF(A:A,A20) -> 1 | T20: =IF(OR(H20="",LOWER(TRIM(H20&""))="missing",LOWER(TRIM(H20&""))=""),"Missing/",IFERROR(IF(OR(VALUE(H20)<0,VALUE(H20)>110),"Invalid","Valid"),"Check Format")) -> Missing/ | U20: =IF(Raw_Data[[#This Row],[Age_Check]]="Valid",H20,"") | V20: =IF(OR(K20="",UPPER(TRIM(K20&""))="",LOWER(TRIM(K20&""))="",LOWER(TRIM(K20&""))="",LOWER(TRIM(K20&""))="missing"),"Missing/",IFERROR(IF(VALUE(K20)<0,"Invalid","Valid"),"Check Format")) -> Valid | W20: =IF(OR(E20="",F20=""),"Missing Date/Time",IFERROR(IF(F20>E20,"Arrival After Appointment","OK"),"Check Format")) -> OK | X20: =IF(OR(F20="",G20=""),"Missing Date/Time",IFERROR(IF(G20<F20,"Discharge Before Arrival","OK"),"Check Format")) -> OK
A21: A00020 | B21: P10419 | C21: Ulster Hospital | D21: Out Patient | E21: 04-29-2025 18:10 | F21: 45776.752 | G21: 45776.831 | H21: 18 | I21: M | J21: Cancelled | K21: 90 | L21: 16 | M21: Online | O21: 0 | P21: No | Q21: 120.26 | R21: HIS | S21: =COUNTIF(A:A,A21) -> 1 | T21: =IF(OR(H21="",LOWER(TRIM(H21&""))="missing",LOWER(TRIM(H21&""))=""),"Missing/",IFERROR(IF(OR(VALUE(H21)<0,VALUE(H21)>110),"Invalid","Valid"),"Check Format")) -> Valid | U21: =IF(Raw_Data[[#This Row],[Age_Check]]="Valid",H21,"") -> 18 | V21: =IF(OR(K21="",UPPER(TRIM(K21&""))="",LOWER(TRIM(K21&""))="",LOWER(TRIM(K21&""))="",LOWER(TRIM(K21&""))="missing"),"Missing/",IFERROR(IF(VALUE(K21)<0,"Invalid","Valid"),"Check Format")) -> Valid | W21: =IF(OR(E21="",F21=""),"Missing Date/Time",IFERROR(IF(F21>E21,"Arrival After Appointment","OK"),"Check Format")) -> OK | X21: =IF(OR(F21="",G21=""),"Missing Date/Time",IFERROR(IF(G21<F21,"Discharge Before Arrival","OK"),"Check Format")) -> OK
A22: A00021 | B22: P10285 | C22: Ulster Hospital | D22: Accident & Emergency | E22: 45297.354 | F22: 45297.352 | G22: 45297.436 | H22: 145 | J22: D | K22: 69 | L22: 49 | M22: Walk-in | N22: BT9 | O22: 0 | Q22: 106.67 | R22: HIS | S22: =COUNTIF(A:A,A22) -> 1 | T22: =IF(OR(H22="",LOWER(TRIM(H22&""))="missing",LOWER(TRIM(H22&""))=""),"Missing/",IFERROR(IF(OR(VALUE(H22)<0,VALUE(H22)>110),"Invalid","Valid"),"Check Format")) -> Invalid | U22: =IF(Raw_Data[[#This Row],[Age_Check]]="Valid",H22,"") | V22: =IF(OR(K22="",UPPER(TRIM(K22&""))="",LOWER(TRIM(K22&""))="",LOWER(TRIM(K22&""))="",LOWER(TRIM(K22&""))="missing"),"Missing/",IFERROR(IF(VALUE(K22)<0,"Invalid","Valid"),"Check Format")) -> Valid | W22: =IF(OR(E22="",F22=""),"Missing Date/Time",IFERROR(IF(F22>E22,"Arrival After Appointment","OK"),"Check Format")) -> OK | X22: =IF(OR(F22="",G22=""),"Missing Date/Time",IFERROR(IF(G22<F22,"Discharge Before Arrival","OK"),"Check Format")) -> OK
A23: A00022 | B23: P10122 | C23: Belfast City Hospital | D23: Neurology | E23: 45557.451 | F23: 45557.436 | G23: 45557.495 | J23: Pending | K23: 51 | L23: 12 | M23: Emergency | N23: BT7 | O23: 0 | P23: No | Q23: 49.3 | R23: ClinicSystem | S23: =COUNTIF(A:A,A23) -> 1 | T23: =IF(OR(H23="",LOWER(TRIM(H23&""))="missing",LOWER(TRIM(H23&""))=""),"Missing/",IFERROR(IF(OR(VALUE(H23)<0,VALUE(H23)>110),"Invalid","Valid"),"Check Format")) -> Missing/ | U23: =IF(Raw_Data[[#This Row],[Age_Check]]="Valid",H23,"") | V23: =IF(OR(K23="",UPPER(TRIM(K23&""))="",LOWER(TRIM(K23&""))="",LOWER(TRIM(K23&""))="",LOWER(TRIM(K23&""))="missing"),"Missing/",IFERROR(IF(VALUE(K23)<0,"Invalid","Valid"),"Check Format")) -> Valid | W23: =IF(OR(E23="",F23=""),"Missing Date/Time",IFERROR(IF(F23>E23,"Arrival After Appointment","OK"),"Check Format")) -> OK | X23: =IF(OR(F23="",G23=""),"Missing Date/Time",IFERROR(IF(G23<F23,"Discharge Before Arrival","OK"),"Check Format")) -> OK
A24: A00023 | B24: P10194 | D24: CARDIOLOGY | E24: 45717.302 | G24: 45717.401 | H24: 145 | J24: Completed | K24: 86 | L24: 56 | M24: Specialist | N24: BT9 | O24: 0 | P24: No | R24: LegacyDB | S24: =COUNTIF(A:A,A24) -> 1 | T24: =IF(OR(H24="",LOWER(TRIM(H24&""))="missing",LOWER(TRIM(H24&""))=""),"Missing/",IFERROR(IF(OR(VALUE(H24)<0,VALUE(H24)>110),"Invalid","Valid"),"Check Format")) -> Invalid | U24: =IF(Raw_Data[[#This Row],[Age_Check]]="Valid",H24,"") | V24: =IF(OR(K24="",UPPER(TRIM(K24&""))="",LOWER(TRIM(K24&""))="",LOWER(TRIM(K24&""))="",LOWER(TRIM(K24&""))="missing"),"Missing/",IFERROR(IF(VALUE(K24)<0,"Invalid","Valid"),"Check Format")) -> Valid | W24: =IF(OR(E24="",F24=""),"Missing Date/Time",IFERROR(IF(F24>E24,"Arrival After Appointment","OK"),"Check Format")) -> Missing Date/Time | X24: =IF(OR(F24="",G24=""),"Missing Date/Time",IFERROR(IF(G24<F24,"Discharge Before Arrival","OK"),"Check Format")) -> Missing Date/Time
A25: A00024 | B25: P10288 | C25: Belfast City Hospital | D25: Emergency | E25: 45770.406 | F25: 45770.397 | G25: 45770.479 | H25: 59 | I25: Non-binary | K25: 55 | L25: 50 | N25: BT15 | P25: Yes | Q25: 173.93 | R25: HIS | S25: =COUNTIF(A:A,A25) -> 1 | T25: =IF(OR(H25="",LOWER(TRIM(H25&""))="missing",LOWER(TRIM(H25&""))=""),"Missing/",IFERROR(IF(OR(VALUE(H25)<0,VALUE(H25)>110),"Invalid","Valid"),"Check Format")) -> Valid | U25: =IF(Raw_Data[[#This Row],[Age_Check]]="Valid",H25,"") -> 59 | V25: =IF(OR(K25="",UPPER(TRIM(K25&""))="",LOWER(TRIM(K25&""))="",LOWER(TRIM(K25&""))="",LOWER(TRIM(K25&""))="missing"),"Missing/",IFERROR(IF(VALUE(K25)<0,"Invalid","Valid"),"Check Format")) -> Valid | W25: =IF(OR(E25="",F25=""),"Missing Date/Time",IFERROR(IF(F25>E25,"Arrival After Appointment","OK"),"Check Format")) -> OK | X25: =IF(OR(F25="",G25=""),"Missing Date/Time",IFERROR(IF(G25<F25,"Discharge Before Arrival","OK"),"Check Format")) -> OK
A26: A00025 | B26: P10332 | C26: Royal Victoria Hospital | D26: Emergency | E26: 03-24-2024 14:00 | F26: 45375.569 | H26: 31 | I26: F | K26: 35 | L26: 38 | M26: Self-referral | N26: BT9 | P26: Yes | Q26: 268.04 | R26: ClinicSystem | S26: =COUNTIF(A:A,A26) -> 1 | T26: =IF(OR(H26="",LOWER(TRIM(H26&""))="missing",LOWER(TRIM(H26&""))=""),"Missing/",IFERROR(IF(OR(VALUE(H26)<0,VALUE(H26)>110),"Invalid","Valid"),"Check Format")) -> Valid | U26: =IF(Raw_Data[[#This Row],[Age_Check]]="Valid",H26,"") -> 31 | V26: =IF(OR(K26="",UPPER(TRIM(K26&""))="",LOWER(TRIM(K26&""))="",LOWER(TRIM(K26&""))="",LOWER(TRIM(K26&""))="missing"),"Missing/",IFERROR(IF(VALUE(K26)<0,"Invalid","Valid"),"Check Format")) -> Valid | W26: =IF(OR(E26="",F26=""),"Missing Date/Time",IFERROR(IF(F26>E26,"Arrival After Appointment","OK"),"Check Format")) -> OK | X26: =IF(OR(F26="",G26=""),"Missing Date/Time",IFERROR(IF(G26<F26,"Discharge Before Arrival","OK"),"Check Format")) -> Missing Date/Time
A27: A00026 | B27: P10055 | C27: Belfast City Hospital | D27: Neurology | E27: 45912.705 | F27: 45912.692 | G27: 45912.785 | I27: M | J27: Cancelled | K27: 56 | L27: 60 | M27: Emergency | Q27: 0 | R27: Legacy DB | S27: =COUNTIF(A:A,A27) -> 1 | T27: =IF(OR(H27="",LOWER(TRIM(H27&""))="missing",LOWER(TRIM(H27&""))=""),"Missing/",IFERROR(IF(OR(VALUE(H27)<0,VALUE(H27)>110),"Invalid","Valid"),"Check Format")) -> Missing/ | U27: =IF(Raw_Data[[#This Row],[Age_Check]]="Valid",H27,"") | V27: =IF(OR(K27="",UPPER(TRIM(K27&""))="",LOWER(TRIM(K27&""))="",LOWER(TRIM(K27&""))="",LOWER(TRIM(K27&""))="missing"),"Missing/",IFERROR(IF(VALUE(K27)<0,"Invalid","Valid"),"Check Format")) -> Valid | W27: =IF(OR(E27="",F27=""),"Missing Date/Time",IFERROR(IF(F27>E27,"Arrival After Appointment","OK"),"Check Format")) -> OK | X27: =IF(OR(F27="",G27=""),"Missing Date/Time",IFERROR(IF(G27<F27,"Discharge Before Arrival","OK"),"Check Format")) -> OK
A28: A00027 | B28: P10259 | C28: RVH | D28: Pediatrics | E28: 45628.528 | G28: 45334.61 | I28: Prefer not to say | J28: Completed | K28: 86 | L28: 33 | M28: Online | N28: BT7 | P28: Yes | Q28: 121.08 | R28: LegacyDB | S28: =COUNTIF(A:A,A28) -> 1 | T28: =IF(OR(H28="",LOWER(TRIM(H28&""))="missing",LOWER(TRIM(H28&""))=""),"Missing/",IFERROR(IF(OR(VALUE(H28)<0,VALUE(H28)>110),"Invalid","Valid"),"Check Format")) -> Missing/ | U28: =IF(Raw_Data[[#This Row],[Age_Check]]="Valid",H28,"") | V28: =IF(OR(K28="",UPPER(TRIM(K28&""))="",LOWER(TRIM(K28&""))="",LOWER(TRIM(K28&""))="",LOWER(TRIM(K28&""))="missing"),"Missing/",IFERROR(IF(VALUE(K28)<0,"Invalid","Valid"),"Check Format")) -> Valid | W28: =IF(OR(E28="",F28=""),"Missing Date/Time",IFERROR(IF(F28>E28,"Arrival After Appointment","OK"),"Check Format")) -> Missing Date/Time | X28: =IF(OR(F28="",G28=""),"Missing Date/Time",IFERROR(IF(G28<F28,"Discharge Before Arrival","OK"),"Check Format")) -> Missing Date/Time
A29: A00028 | B29: P10142 | D29: Cardiology | E29: 45768.58 | F29: 45768.57 | G29: 45768.626 | I29: F | J29: Pending | K29: 61 | L29: 5 | M29: Online | N29: BT15 | O29: 4 | P29: Yes | Q29: 127.43 | R29: LegacyDB | S29: =COUNTIF(A:A,A29) -> 1 | T29: =IF(OR(H29="",LOWER(TRIM(H29&""))="missing",LOWER(TRIM(H29&""))=""),"Missing/",IFERROR(IF(OR(VALUE(H29)<0,VALUE(H29)>110),"Invalid","Valid"),"Check Format")) -> Missing/ | U29: =IF(Raw_Data[[#This Row],[Age_Check]]="Valid",H29,"") | V29: =IF(OR(K29="",UPPER(TRIM(K29&""))="",LOWER(TRIM(K29&""))="",LOWER(TRIM(K29&""))="",LOWER(TRIM(K29&""))="missing"),"Missing/",IFERROR(IF(VALUE(K29)<0,"Invalid","Valid"),"Check Format")) -> Valid | W29: =IF(OR(E29="",F29=""),"Missing Date/Time",IFERROR(IF(F29>E29,"Arrival After Appointment","OK"),"Check Format")) -> OK | X29: =IF(OR(F29="",G29=""),"Missing Date/Time",IFERROR(IF(G29<F29,"Discharge Before Arrival","OK"),"Check Format")) -> OK
A30: A00029 | B30: P10208 | D30: A&E | E30: 45861.319 | F30: 45861.315 | G30: 45861.408 | I30: M | J30: D | K30: 70 | L30: 58 | M30: GP | N30: BT2 | O30: 0 | P30: No | Q30: 103.54 | R30: Legacy DB | S30: =COUNTIF(A:A,A30) -> 1 | T30: =IF(OR(H30="",LOWER(TRIM(H30&""))="missing",LOWER(TRIM(H30&""))=""),"Missing/",IFERROR(IF(OR(VALUE(H30)<0,VALUE(H30)>110),"Invalid","Valid"),"Check Format")) -> Missing/ | U30: =IF(Raw_Data[[#This Row],[Age_Check]]="Valid",H30,"") | V30: =IF(OR(K30="",UPPER(TRIM(K30&""))="",LOWER(TRIM(K30&""))="",LOWER(TRIM(K30&""))="",LOWER(TRIM(K30&""))="missing"),"Missing/",IFERROR(IF(VALUE(K30)<0,"Invalid","Valid"),"Check Format")) -> Valid | W30: =IF(OR(E30="",F30=""),"Missing Date/Time",IFERROR(IF(F30>E30,"Arrival After Appointment","OK"),"Check Format")) -> OK | X30: =IF(OR(F30="",G30=""),"Missing Date/Time",IFERROR(IF(G30<F30,"Discharge Before Arrival","OK"),"Check Format")) -> OK
A31: A00030 | B31: P10118 | C31: Royal Victoria Hospital | D31: Out Patient | E31: 07-17-2025 12:25 | F31: 45855.51 | H31: 88 | I31: M | J31: Cancelled | K31: 29 | L31: 22 | M31: Specialist | N31: BT9 | O31: 6 | P31: Yes | Q31: 218.23 | R31: HIS | S31: =COUNTIF(A:A,A31) -> 1 | T31: =IF(OR(H31="",LOWER(TRIM(H31&""))="missing",LOWER(TRIM(H31&""))=""),"Missing/",IFERROR(IF(OR(VALUE(H31)<0,VALUE(H31)>110),"Invalid","Valid"),"Check Format")) -> Valid | U31: =IF(Raw_Data[[#This Row],[Age_Check]]="Valid",H31,"") -> 88 | V31: =IF(OR(K31="",UPPER(TRIM(K31&""))="",LOWER(TRIM(K31&""))="",LOWER(TRIM(K31&""))="",LOWER(TRIM(K31&""))="missing"),"Missing/",IFERROR(IF(VALUE(K31)<0,"Invalid","Valid"),"Check Format")) -> Valid | W31: =IF(OR(E31="",F31=""),"Missing Date/Time",IFERROR(IF(F31>E31,"Arrival After Appointment","OK"),"Check Format")) -> OK | X31: =IF(OR(F31="",G31=""),"Missing Date/Time",IFERROR(IF(G31<F31,"Discharge Before Arrival","OK"),"Check Format")) -> Missing Date/Time
A32: A00031 | B32: P10027 | C32: Belfast City Hospital | D32: Accident & Emergency | E32: 45423.33 | F32: 45601.327 | G32: 45601.393 | H32: 62 | K32: 69 | L32: 22 | M32: GP | N32: BT9 | P32: No | Q32: 186.06 | R32: LegacyDB | S32: =COUNTIF(A:A,A32) -> 1 | T32: =IF(OR(H32="",LOWER(TRIM(H32&""))="missing",LOWER(TRIM(H32&""))=""),"Missing/",IFERROR(IF(OR(VALUE(H32)<0,VALUE(H32)>110),"Invalid","Valid"),"Check Format")) -> Valid | U32: =IF(Raw_Data[[#This Row],[Age_Check]]="Valid",H32,"") -> 62 | V32: =IF(OR(K32="",UPPER(TRIM(K32&""))="",LOWER(TRIM(K32&""))="",LOWER(TRIM(K32&""))="",LOWER(TRIM(K32&""))="missing"),"Missing/",IFERROR(IF(VALUE(K32)<0,"Invalid","Valid"),"Check Format")) -> Valid | W32: =IF(OR(E32="",F32=""),"Missing Date/Time",IFERROR(IF(F32>E32,"Arrival After Appointment","OK"),"Check Format")) -> Arrival After Appointment | X32: =IF(OR(F32="",G32=""),"Missing Date/Time",IFERROR(IF(G32<F32,"Discharge Before Arrival","OK"),"Check Format")) -> OK
A33: A00032 | B33: P10155 | C33: Royal Victoria Hospital | D33: Accident & Emergency | E33: 45702.587 | F33: 45702.585 | G33: 45702.663 | H33: 145 | J33: Completed | K33: 61 | L33: 49 | M33: Specialist | O33: 0 | P33: Yes | Q33: 88.84 | R33: HIS | S33: =COUNTIF(A:A,A33) -> 1 | T33: =IF(OR(H33="",LOWER(TRIM(H33&""))="missing",LOWER(TRIM(H33&""))=""),"Missing/",IFERROR(IF(OR(VALUE(H33)<0,VALUE(H33)>110),"Invalid","Valid"),"Check Format")) -> Invalid | U33: =IF(Raw_Data[[#This Row],[Age_Check]]="Valid",H33,"") | V33: =IF(OR(K33="",UPPER(TRIM(K33&""))="",LOWER(TRIM(K33&""))="",LOWER(TRIM(K33&""))="",LOWER(TRIM(K33&""))="missing"),"Missing/",IFERROR(IF(VALUE(K33)<0,"Invalid","Valid"),"Check Format")) -> Valid | W33: =IF(OR(E33="",F33=""),"Missing Date/Time",IFERROR(IF(F33>E33,"Arrival After Appointment","OK"),"Check Format")) -> OK | X33: =IF(OR(F33="",G33=""),"Missing Date/Time",IFERROR(IF(G33<F33,"Discharge Before Arrival","OK"),"Check Format")) -> OK
A34: A00033 | B34: P10122 | C34: Mater Hospital | D34: Out Patient | E34: 45393.451 | F34: 45393.448 | H34: 145 | I34: M | J34: D | K34: 46 | L34: 24 | M34: GP | N34: BT1 | P34: Yes | Q34: 27.92 | R34: HIS | S34: =COUNTIF(A:A,A34) -> 1 | T34: =IF(OR(H34="",LOWER(TRIM(H34&""))="missing",LOWER(TRIM(H34&""))=""),"Missing/",IFERROR(IF(OR(VALUE(H34)<0,VALUE(H34)>110),"Invalid","Valid"),"Check Format")) -> Invalid | U34: =IF(Raw_Data[[#This Row],[Age_Check]]="Valid",H34,"") | V34: =IF(OR(K34="",UPPER(TRIM(K34&""))="",LOWER(TRIM(K34&""))="",LOWER(TRIM(K34&""))="",LOWER(TRIM(K34&""))="missing"),"Missing/",IFERROR(IF(VALUE(K34)<0,"Invalid","Valid"),"Check Format")) -> Valid | W34: =IF(OR(E34="",F34=""),"Missing Date/Time",IFERROR(IF(F34>E34,"Arrival After Appointment","OK"),"Check Format")) -> OK | X34: =IF(OR(F34="",G34=""),"Missing Date/Time",IFERROR(IF(G34<F34,"Discharge Before Arrival","OK"),"Check Format")) -> Missing Date/Time
A35: A00034 | B35: P10115 | C35: Mater Hospital | D35: CARDIOLOGY | E35: 45932.701 | F35: 45932.683 | G35: 45932.774 | J35: D | K35: 68 | L35: 36 | M35: GP | N35: BT9 | P35: Yes | Q35: 145.41 | R35: LegacyDB | S35: =COUNTIF(A:A,A35) -> 1 | T35: =IF(OR(H35="",LOWER(TRIM(H35&""))="missing",LOWER(TRIM(H35&""))=""),"Missing/",IFERROR(IF(OR(VALUE(H35)<0,VALUE(H35)>110),"Invalid","Valid"),"Check Format")) -> Missing/ | U35: =IF(Raw_Data[[#This Row],[Age_Check]]="Valid",H35,"") | V35: =IF(OR(K35="",UPPER(TRIM(K35&""))="",LOWER(TRIM(K35&""))="",LOWER(TRIM(K35&""))="",LOWER(TRIM(K35&""))="missing"),"Missing/",IFERROR(IF(VALUE(K35)<0,"Invalid","Valid"),"Check Format")) -> Valid | W35: =IF(OR(E35="",F35=""),"Missing Date/Time",IFERROR(IF(F35>E35,"Arrival After Appointment","OK"),"Check Format")) -> OK | X35: =IF(OR(F35="",G35=""),"Missing Date/Time",IFERROR(IF(G35<F35,"Discharge Before Arrival","OK"),"Check Format")) -> OK
A36: A00035 | B36: P10046 | C36: Ulster Hospital | D36: Paediatrics | E36: 45567.58 | F36: 45332.562 | G36: 45332.618 | I36: Non-binary | J36: Discharged | K36: 49 | L36: 6 | M36: GP | N36: BT7 | P36: No | Q36: 111.35 | R36: ClinicSystem | S36: =COUNTIF(A:A,A36) -> 1 | T36: =IF(OR(H36="",LOWER(TRIM(H36&""))="missing",LOWER(TRIM(H36&""))=""),"Missing/",IFERROR(IF(OR(VALUE(H36)<0,VALUE(H36)>110),"Invalid","Valid"),"Check Format")) -> Missing/ | U36: =IF(Raw_Data[[#This Row],[Age_Check]]="Valid",H36,"") | V36: =IF(OR(K36="",UPPER(TRIM(K36&""))="",LOWER(TRIM(K36&""))="",LOWER(TRIM(K36&""))="",LOWER(TRIM(K36&""))="missing"),"Missing/",IFERROR(IF(VALUE(K36)<0,"Invalid","Valid"),"Check Format")) -> Valid | W36: =IF(OR(E36="",F36=""),"Missing Date/Time",IFERROR(IF(F36>E36,"Arrival After Appointment","OK"),"Check Format")) -> OK | X36: =IF(OR(F36="",G36=""),"Missing Date/Time",IFERROR(IF(G36<F36,"Discharge Before Arrival","OK"),"Check Format")) -> OK
A37: A00036 | B37: P10053 | C37: Mater Hospital | D37: Cardiology | F37: 45385.585 | G37: 45385.644 | H37: 145 | I37: F | J37: Completed | K37: 46 | L37: 17 | M37: Online | N37: BT2 | P37: Yes | Q37: 132.1 | R37: HIS | S37: =COUNTIF(A:A,A37) -> 1 | T37: =IF(OR(H37="",LOWER(TRIM(H37&""))="missing",LOWER(TRIM(H37&""))=""),"Missing/",IFERROR(IF(OR(VALUE(H37)<0,VALUE(H37)>110),"Invalid","Valid"),"Check Format")) -> Invalid | U37: =IF(Raw_Data[[#This Row],[Age_Check]]="Valid",H37,"") | V37: =IF(OR(K37="",UPPER(TRIM(K37&""))="",LOWER(TRIM(K37&""))="",LOWER(TRIM(K37&""))="",LOWER(TRIM(K37&""))="missing"),"Missing/",IFERROR(IF(VALUE(K37)<0,"Invalid","Valid"),"Check Format")) -> Valid | W37: =IF(OR(E37="",F37=""),"Missing Date/Time",IFERROR(IF(F37>E37,"Arrival After Appointment","OK"),"Check Format")) -> Missing Date/Time | X37: =IF(OR(F37="",G37=""),"Missing Date/Time",IFERROR(IF(G37<F37,"Discharge Before Arrival","OK"),"Check Format")) -> OK
A38: A00037 | B38: P10387 | D38: Outpatient | E38: 45907.604 | F38: 45847.588 | H38: 70 | I38: Non-binary | J38: Completed | K38: 72 | L38: 65 | M38: Online | N38: BT9 | P38: Yes | Q38: 158.97 | R38: ClinicSystem | S38: =COUNTIF(A:A,A38) -> 1 | T38: =IF(OR(H38="",LOWER(TRIM(H38&""))="missing",LOWER(TRIM(H38&""))=""),"Missing/",IFERROR(IF(OR(VALUE(H38)<0,VALUE(H38)>110),"Invalid","Valid"),"Check Format")) -> Valid | U38: =IF(Raw_Data[[#This Row],[Age_Check]]="Valid",H38,"") -> 70 | V38: =IF(OR(K38="",UPPER(TRIM(K38&""))="",LOWER(TRIM(K38&""))="",LOWER(TRIM(K38&""))="",LOWER(TRIM(K38&""))="missing"),"Missing/",IFERROR(IF(VALUE(K38)<0,"Invalid","Valid"),"Check Format")) -> Valid | W38: =IF(OR(E38="",F38=""),"Missing Date/Time",IFERROR(IF(F38>E38,"Arrival After Appointment","OK"),"Check Format")) -> OK | X38: =IF(OR(F38="",G38=""),"Missing Date/Time",IFERROR(IF(G38<F38,"Discharge Before Arrival","OK"),"Check Format")) -> Missing Date/Time
A39: A00038 | B39: P10366 | C39: Belfast City Hospital | D39: Pediatrics | E39: 45522.358 | F39: 45522.352 | G39: 45522.425 | H39: 60 | I39: M | J39: Cancelled | K39: 67 | L39: 30 | M39: Self-referral | N39: BT7 | O39: 6 | P39: No | Q39: 0 | R39: HIS | S39: =COUNTIF(A:A,A39) -> 1 | T39: =IF(OR(H39="",LOWER(TRIM(H39&""))="missing",LOWER(TRIM(H39&""))=""),"Missing/",IFERROR(IF(OR(VALUE(H39)<0,VALUE(H39)>110),"Invalid","Valid"),"Check Format")) -> Valid | U39: =IF(Raw_Data[[#This Row],[Age_Check]]="Valid",H39,"") -> 60 | V39: =IF(OR(K39="",UPPER(TRIM(K39&""))="",LOWER(TRIM(K39&""))="",LOWER(TRIM(K39&""))="",LOWER(TRIM(K39&""))="missing"),"Missing/",IFERROR(IF(VALUE(K39)<0,"Invalid","Valid"),"Check Format")) -> Valid | W39: =IF(OR(E39="",F39=""),"Missing Date/Time",IFERROR(IF(F39>E39,"Arrival After Appointment","OK"),"Check Format")) -> OK | X39: =IF(OR(F39="",G39=""),"Missing Date/Time",IFERROR(IF(G39<F39,"Discharge Before Arrival","OK"),"Check Format")) -> OK
A40: A00039 | B40: P10296 | D40: Oncology | E40: 2025-19-40 12:30 | F40: 45811.449 | G40: 45811.521 | H40: 145 | J40: Pending | K40: 57 | L40: 33 | N40: BT9 | P40: No | Q40: 342.06 | R40: ClinicSystem | S40: =COUNTIF(A:A,A40) -> 1 | T40: =IF(OR(H40="",LOWER(TRIM(H40&""))="missing",LOWER(TRIM(H40&""))=""),"Missing/",IFERROR(IF(OR(VALUE(H40)<0,VALUE(H40)>110),"Invalid","Valid"),"Check Format")) -> Invalid | U40: =IF(Raw_Data[[#This Row],[Age_Check]]="Valid",H40,"") | V40: =IF(OR(K40="",UPPER(TRIM(K40&""))="",LOWER(TRIM(K40&""))="",LOWER(TRIM(K40&""))="",LOWER(TRIM(K40&""))="missing"),"Missing/",IFERROR(IF(VALUE(K40)<0,"Invalid","Valid"),"Check Format")) -> Valid | W40: =IF(OR(E40="",F40=""),"Missing Date/Time",IFERROR(IF(F40>E40,"Arrival After Appointment","OK"),"Check Format")) -> OK | X40: =IF(OR(F40="",G40=""),"Missing Date/Time",IFERROR(IF(G40<F40,"Discharge Before Arrival","OK"),"Check Format")) -> OK
...

Sheet Duplicate_investigation
A1: Column1 | B1: patient_id | C1: hospital | D1: department | E1: appointment_datetime | F1: arrival_datetime | G1: discharge_datetime | H1: age | I1: gender | J1: appointment_status | K1: waiting_time_minutes | L1: consultation_duration_minutes | M1: referral_source | N1: postcode_area | O1: patient_satisfaction | P1: follow_up_required | Q1: cost_gbp | R1: data_source | S1: ID_Count | T1: Same_Patient? | U1: Same_Appointment_Details? | V1: Recommended_Action
A2: A00049 | B2: P10056 | C2: Belfast City Hospital | D2: Orthopedics | E2: 45352.465 | F2: 45294.458 | G2: 45294.549 | I2: Female | J2: No-show | K2: 65 | L2: 55 | M2: Self-referral | N2: BT12 | O2: N/A | P2: N | Q2: 16.4 | R2: HIS | S2: 2 | T2: YES | U2: YES | V2: Remove
A3: A00049 | B3: P10056 | C3: Belfast City Hospital | D3: Orthopedics | E3: 45352.465 | F3: 45294.458 | G3: 45294.549 | I3: Female | J3: No-show | K3: 65 | L3: 55 | M3: Self-referral | N3: BT12 | O3: N/A | P3: N | Q3: 16.4 | R3: HIS | S3: 2 | T3: YES | U3: YES | V3: Remove
A4: A00057 | B4: P10410 | D4: Emergency | E4: 45719.462 | F4: 45719.442 | G4: 45719.552 | H4: 13 | I4: female | J4: complete | K4: 91 | L4: 39 | N4: UNKNOWN | P4: No | Q4: 210.76 | R4: LegacyDB | S4: 2 | T4: NO | U4: NO | V4: Keep
A5: A00057 | B5: P10052 | C5: Mater Hospital | D5: Cardiology | E5: 45835.635 | F5: 45835.632 | G5: 45835.74 | H5: 9 | I5: MALE | J5: Discharged | K5: 124 | L5: 27 | M5: Online | O5: N/A | P5: yes | Q5: 84.7 | R5: Legacy DB | S5: 2 | T5: NO | U5: NO | V5: Keep
A6: A00121 | B6: P10440 | C6: Mater Hosp. | D6: Emergency | E6: 06-15-2025 17:35 | F6: 45823.722 | H6: unknown | I6: Male | J6: Completed | K6: 109 | L6: 47 | M6: Emergency | N6: BT15 | O6: 3 | P6: N | Q6: 132.2 | R6: ClinicSystem | S6: 2 | T6: YES | U6: YES | V6: Remove
A7: A00121 | B7: P10440 | C7: Mater Hosp. | D7: Emergency | E7: 06-15-2025 17:35 | F7: 45823.722 | H7: unknown | I7: Male | J7: Completed | K7: 109 | L7: 47 | M7: Emergency | N7: BT15 | O7: 3 | P7: N | Q7: 132.2 | R7: ClinicSystem | S7: 2 | T7: YES | U7: YES | V7: Remove
A8: A00159 | B8: P10368 | C8: Royal Victoria Hospital | D8: CARDIOLOGY | E8: 45568.698 | F8: 45568.681 | H8: 77 | I8: Non-binary | J8: No-show | K8: 54 | L8: 28 | M8: Specialist | N8: BT15 | O8: 3 | P8: Yes | Q8: 194.13 | R8: ClinicSystem | S8: 2 | T8: YES | U8: YES | V8: Remove
A9: A00159 | B9: P10368 | C9: Royal Victoria Hospital | D9: CARDIOLOGY | E9: 45568.698 | F9: 45568.681 | H9: 77 | I9: Non-binary | J9: No-show | K9: 54 | L9: 28 | M9: Specialist | N9: BT15 | O9: 3 | P9: Yes | Q9: 194.13 | R9: ClinicSystem | S9: 2 | T9: YES | U9: YES | V9: Remove
A10: A00184 | B10: P10134 | C10: Mater Hospital | D10: Oncology | F10: 45332.717 | G10: 45332.791 | H10: 145 | I10: Non-binary | J10: Cancelled | K10: 44 | L10: 50 | N10: BT9 | Q10: 98.85 | R10: HIS | S10: 2 | T10: NO | U10: NO | V10: Keep
A11: A00184 | B11: P10076 | C11: Mater Hospital | D11: A&E | E11: 05-22-2024 14:10 | F11: 45434.577 | G11: 45434.658 | H11: 84 | I11: female | J11: DNA | K11: 87 | L11: 11 | M11: Walk-in | N11: BT2 | O11: 0 | P11: No | Q11: 187.38 | R11: HIS | S11: 2 | T11: NO | U11: NO | V11: Keep
A12: A00191 | B12: P10109 | C12: Mater Hosp. | D12: Orthopaedics | E12: 45967.372 | F12: 45967.354 | G12: 45967.428 | H12: unknown | I12: Female | J12: DNA | K12: 42 | L12: 39 | M12: Self-referral | N12: bt7 | O12: 1 | P12: N | Q12: 111.32 | R12: HIS | S12: 2 | T12: YES | U12: YES | V12: Remove
A13: A00191 | B13: P10109 | C13: Mater Hosp. | D13: Orthopaedics | E13: 45967.372 | F13: 45967.354 | G13: 45967.428 | H13: unknown | I13: Female | J13: DNA | K13: 42 | L13: 39 | M13: Self-referral | N13: bt7 | O13: 1 | P13: N | Q13: 111.32 | R13: HIS | S13: 2 | T13: YES | U13: YES | V13: Remove
A14: A00237 | B14: P10291 | C14: Belfast City Hospital | D14: Cardiology | E14: 45623.295 | F14: 45623.291 | G14: 45623.379 | H14: -4 | I14: MALE | J14: Discharged | K14: 79 | L14: 42 | M14: GP | N14: BT7 | O14: N/A | P14: N | Q14: 120.24 | R14: Legacy DB | S14: 2 | T14: NO | U14: NO | V14: Keep
A15: A00237 | B15: P10295 | C15: RVH | D15: Orthopedics | E15: 45349.639 | F15: 45349.619 | G15: 45349.693 | I15: Female | J15: Discharged | K15: 69 | L15: 9 | M15: Walk-in | N15: bt7 | O15: 6 | P15: yes | Q15: 218.92 | R15: Legacy DB | S15: 2 | T15: NO | U15: NO | V15: Keep
A16: A00276 | B16: P10089 | C16: Mater Hospital | D16: Oncology | E16: 45965.406 | F16: 45758.404 | H16: 73 | I16: MALE | J16: No-show | K16: 101 | L16: 15 | M16: GP | N16: BT15 | O16: 6 | P16: No | R16: LegacyDB | S16: 2 | T16: YES | U16: YES | V16: Remove
A17: A00276 | B17: P10089 | C17: Mater Hospital | D17: Oncology | E17: 45965.406 | F17: 45758.404 | H17: 73 | I17: MALE | J17: No-show | K17: 101 | L17: 15 | M17: GP | N17: BT15 | O17: 6 | P17: No | R17: LegacyDB | S17: 2 | T17: YES | U17: YES | V17: Remove
A18: A00289 | B18: P10437 | C18: Mater Hosp. | D18: Orthopedics | E18: 45611.733 | F18: 45611.731 | G18: 45611.806 | I18: F | J18: DNA | K18: 71 | L18: 34 | M18: GP | N18: BT99 | O18: 0 | P18: yes | Q18: 184.4 | R18: HIS | S18: 2 | T18: NO | U18: NO | V18: Keep
A19: A00289 | B19: P10102 | C19: Mater Hosp. | D19: Cardiology | E19: 45396.757 | F19: 45396.739 | G19: 45396.857 | H19: unknown | J19: Cancelled | K19: 68 | L19: 76 | M19: GP | N19: bt7 | O19: N/A | P19: yes | Q19: 93.98 | R19: HIS | S19: 2 | T19: NO | U19: NO | V19: Keep
A20: A00347 | B20: P10246 | D20: Out Patient | E20: 45908.41 | F20: 45878.407 | G20: 45878.476 | K20: 33 | L20: 63 | N20: UNKNOWN | O20: 6 | P20: yes | Q20: 160.83 | R20: ClinicSystem | S20: 2 | T20: NO | U20: NO | V20: Keep
A21: A00347 | B21: P10419 | C21: Belfast City Hospital | D21: Emergency | E21: 45300.656 | F21: 45300.652 | G21: 45300.697 | H21: 81 | I21: Prefer not to say | J21: No-show | K21: 35 | L21: 23 | M21: Specialist | N21: BT99 | O21: N/A | P21: Y | Q21: 119.37 | R21: Legacy DB | S21: 2 | T21: NO | U21: NO | V21: Keep
A22: A00368 | B22: P10219 | C22: Ulster Hospital | D22: Out Patient | E22: 45305.417 | F22: 45305.416 | G22: 45305.464 | H22: 37 | I22: F | J22: Cancelled | K22: 60 | L22: 8 | N22: BT9 | O22: N/A | P22: yes | Q22: 224.7 | R22: HIS | S22: 2 | T22: NO | U22: NO | V22: Keep
A23: A00368 | B23: P10117 | C23: RVH | D23: Pediatrics | E23: 10-21-2025 07:40 | F23: 45951.315 | G23: 45951.351 | H23: unknown | I23: M | J23: complete | K23: 40 | L23: 5 | N23: UNKNOWN | O23: 0 | P23: No | R23: HIS | S23: 2 | T23: NO | U23: NO | V23: Keep
A24: A00383 | B24: P10382 | C24: Belfast City Hospital | D24: Accident & Emergency | E24: 10-30-2024 10:35 | F24: 45595.435 | G24: 45595.56 | J24: CANCELLED | K24: 142 | L24: 30 | M24: Online | N24: BT9 | O24: N/A | P24: N | R24: LegacyDB | S24: 2 | T24: YES | U24: YES | V24: Remove
A25: A00383 | B25: P10382 | C25: Belfast City Hospital | D25: Accident & Emergency | E25: 10-30-2024 10:35 | F25: 45595.435 | G25: 45595.56 | J25: CANCELLED | K25: 142 | L25: 30 | M25: Online | N25: BT9 | O25: N/A | P25: N | R25: LegacyDB | S25: 2 | T25: YES | U25: YES | V25: Remove
A26: A00385 | B26: P10155 | D26: Cardiology | E26: 45853.545 | F26: 45853.533 | G26: 45853.644 | I26: F | J26: No-show | K26: 99 | L26: 43 | M26: Specialist | N26: BT9 | P26: No | Q26: 53.56 | R26: HIS | S26: 2 | T26: NO | U26: NO | V26: Keep
A27: A00385 | B27: P10091 | C27: Belfast City Hospital | D27: A&E | E27: 03-13-2025 17:10 | F27: 45729.704 | G27: 45729.803 | H27: 55 | I27: female | J27: Completed | K27: 115 | L27: 11 | M27: Specialist | N27: BT1 | O27: 0 | P27: N | Q27: 169.21 | R27: Legacy DB | S27: 2 | T27: NO | U27: NO | V27: Keep
A28: A00511 | B28: P10262 | C28: Ulster Hospital | D28: Oncology | E28: 11-29-2025 11:15 | F28: 45990.459 | G28: 45990.554 | H28: unknown | I28: F | J28: Discharged | K28: 64 | L28: 59 | M28: Online | N28: BT7 | P28: Y | Q28: 305.49 | R28: Legacy DB | S28: 2 | T28: YES | U28: YES | V28: Remove
A29: A00511 | B29: P10262 | C29: Ulster Hospital | D29: Oncology | E29: 11-29-2025 11:15 | F29: 45990.459 | G29: 45990.554 | H29: unknown | I29: F | J29: Discharged | K29: 64 | L29: 59 | M29: Online | N29: BT7 | P29: Y | Q29: 305.49 | R29: Legacy DB | S29: 2 | T29: YES | U29: YES | V29: Remove
A30: A00612 | B30: P10105 | D30: Outpatient | F30: 45815.297 | G30: 45815.369 | H30: 145 | I30: F | J30: Completed | K30: 62 | L30: 29 | M30: Online | N30: BT99 | Q30: 198.71 | R30: ClinicSystem | S30: 2 | T30: NO | U30: NO | V30: Keep
A31: A00612 | B31: P10227 | C31: Mater Hosp. | D31: Out Patient | E31: 45323.667 | F31: 45323.646 | G31: 45323.724 | H31: 47 | I31: M | J31: Completed | K31: 65 | L31: 18 | N31: BT15 | O31: 0 | P31: No | R31: HIS | S31: 2 | T31: NO | U31: NO | V31: Keep
A32: A00680 | B32: P10230 | C32: Ulster Hospital | D32: Orthopaedics | E32: 45506.424 | F32: 45506.423 | I32: Non-binary | J32: Pending | K32: 84 | L32: 53 | N32: BT7 | O32: 0 | P32: N | R32: LegacyDB | S32: 2 | T32: YES | U32: YES | V32: Remove
A33: A00680 | B33: P10230 | C33: Ulster Hospital | D33: Orthopaedics | E33: 45506.424 | F33: 45506.423 | I33: Non-binary | J33: Pending | K33: 84 | L33: 53 | N33: BT7 | O33: 0 | P33: N | R33: LegacyDB | S33: 2 | T33: YES | U33: YES | V33: Remove
A34: A00689 | B34: P10320 | C34: Belfast city hospital | D34: Oncology | E34: 45833.361 | F34: 45833.347 | G34: 45833.441 | H34: 63 | I34: Unknown | K34: 87 | L34: 28 | M34: Specialist | N34: bt7 | O34: N/A | P34: Yes | Q34: 123.84 | R34: ClinicSystem | S34: 2 | T34: NO | U34: NO | V34: Keep
A35: A00689 | B35: P10152 | C35: Mater Hospital | D35: Orthopedics | E35: 09-25-2025 17:20 | G35: 45925.752 | I35: Unknown | J35: No-show | K35: 0 | L35: 43 | N35: BT9 | P35: Yes | Q35: 45.86 | R35: HIS | S35: 2 | T35: NO | U35: NO | V35: Keep
A36: A00700 | B36: P10152 | C36: Ulster Hospital | D36: Neurology | E36: 45859.319 | F36: 45859.305 | G36: 45859.377 | H36: 67 | I36: female | J36: CANCELLED | K36: 57 | L36: 26 | M36: GP | N36: BT9 | O36: 6 | P36: No | Q36: 157.42 | R36: HIS | S36: 2 | T36: NO | U36: NO | V36: Keep
A37: A00700 | B37: P10146 | C37: Mater Hospital | D37: Paediatrics | E37: 45912.319 | F37: 45912.304 | G37: 45912.39 | H37: 74 | I37: female | J37: Discharged | K37: 86 | L37: 16 | O37: N/A | P37: Y | Q37: 92.35 | R37: Legacy DB | S37: 2 | T37: NO | U37: NO | V37: Keep
A38: A00740 | B38: P10295 | C38: RVH | D38: Accident & Emergency | E38: 07-25-2025 17:30 | F38: 45863.726 | G38: 45863.756 | H38: 48 | K38: 29 | L38: 9 | M38: Specialist | N38: BT15 | O38: 3 | Q38: 126.28 | R38: HIS | S38: 2 | T38: NO | U38: NO | V38: Keep
A39: A00740 | B39: P10117 | D39: GP Referral | E39: 45902.507 | F39: 45902.501 | G39: 45902.592 | I39: Unknown | J39: CANCELLED | K39: 74 | L39: 49 | M39: Walk-in | N39: bt7 | O39: 2 | R39: HIS | S39: 2 | T39: NO | U39: NO | V39: Keep
A40: A00844 | B40: P10127 | C40: Belfast City Hospital | D40: Paediatrics | E40: 03-24-2025 13:10 | F40: 45740.535 | G40: 45740.574 | H40: 10 | I40: M | J40: CANCELLED | K40: 30 | L40: 7 | M40: GP | N40: BT99 | O40: 2 | P40: No | Q40: 169.31 | R40: ClinicSystem | S40: 2 | T40: NO | U40: NO | V40: Keep
...

Sheet Data Quality Audit
A1: Issue ID | B1: Column | C1: Issue Type | D1: Number of Records | E1: Severity | F1: Proposed Action | G1: Validation Result | H1: Cleaning Log
A2: DQ01 | B2: All Columns | C2: Repeated | D2: 78 | E2: Medium | F2: Investigate before removing | G2: Pending
A3: DQ02 | B3: Appoinment_id | C3: Duplicates with conflicting records | D3: 78 | E3: High | F3: investigate whether records are duplicates or separate | G3: Repeated ID's identified; differences between records confirmed
A4: DQ03 | B4: Age | C4: Invalid or missing | D4: 1213 | E4: High | F4: Investigate | G4: 604 invalid; 609 missing or unknown | H4: Removed negative values
A5: DQ04 | B5: Wait_Time | C5: Invalid | D5: 16 | E5: Medium | F5: Investigate | G5: 7 negative and 9 NA | H5: Removed negative values
A6: DQ05 | B6: Consultation | C6: Invalid | D6: 7 | E6: Medium | F6: Investigate | G6: 3 negative , 4 unknown | H6: Removed negative values
A7: DQ06 | B7: Appoinment_time | C7: Invalid | D7: 23 | E7: Medium | F7: Investigate | G7: 2 not recorded , 21 missing | H7: Removed not recorded
A8: DQ07 | B8: Arrival_time | C8: Missing | D8: 111 | E8: High | F8: Investigate before removing | G8: 111 missing values
A9: DQ08 | B9: Discharge_time | C9: Missing | D9: 216 | E9: High | F9: Investigate before removing | G9: 216 missing values
A10: DQ09 | B10: Comparison | C10: Arrival after appoinment time | D10: 81 | E10: High | F10: Investigate | G10: 81 arrival after time and also 131 missing
A11: DQ10 | B11: Comparison | C11: Discharge before arrival | D11: 0 | E11: low | F11: No correction needed | G11: Passed
A12: DQ11 | B12: Patient_Satisfaction | C12: Invalid or missing | D12: 900 | E12: High | F12: Investigate | G12: 277 NA , 312 missing and 311 "0" | H12: Replaced NA as blank
A13: DQ12 | B13: All Columns | C13: Duplicates | D13: 21 | E13: Medium | F13: Remove them | G13: Remove duplicates
I17: Column | J17: Missing record | K17: Percentage
I18: Age | J18: =COUNTBLANK('Raw Data'!H2:H1802) -> 910 | K18: =(J18/1823)*100 -> 49.917718
